<?xml version="1.0" ?>
<!-- =================================================================================== -->
<!-- |    This document was autogenerated by xacro from /home/gianmario/catkin_ws/src/hector_quadrotor/hector_quadrotor_description/urdf/quadrotor_with_kinect.urdf.xacro | -->
<!-- |    EDITING THIS FILE BY HAND IS NOT RECOMMENDED                                 | -->
<!-- =================================================================================== -->
<robot name="quadrotor">
    <link name="base_link">
        
<inertial>
            <mass value="1.477" />
            <origin xyz="0 0 0" />
            <inertia ixx="0.01152" ixy="0.0" ixz="0.0" iyy="0.01152" iyz="0.0" izz="0.0218" />
        </inertial>

        <visual>
            <origin rpy="0 0 0" xyz="0 0 0" />
            <geometry>
                <mesh filename="package://hector_quadrotor_description/meshes/quadrotor/quadrotor_base.dae" />
            </geometry>
        </visual>
        <collision>
            <origin rpy="0 0 0" xyz="0 0 0" />
            <geometry>
                <mesh filename="package://hector_quadrotor_description/meshes/quadrotor/quadrotor_base.stl" />
            </geometry>
        </collision>
    </link>
    <link name="fixedarm_link">
        <visual>
            <origin rpy="0 0 0" xyz="0 0 -0.03" />
            <geometry>
                <cylinder length="0.06" radius="0.01" />
            </geometry>
        </visual>
        <collision>
            <origin rpy="0 0 0" xyz="0 0 -0.03" />
            <geometry>
                <cylinder length="0.06" radius="0.01" />
            </geometry>
        </collision>
        
<inertial>
            <mass value="0.001" />
            <inertia ixx="0.000000325" ixy="0.0" ixz="0.0" iyy="0.000000325" iyz="0.0" izz="0.00000005" />
        </inertial>

    </link>
    <joint name="fixedarm_joint" type="fixed">
        <parent link="base_link" />
        <child link="fixedarm_link" />
        <origin xyz="0 0 -0.03" />
    </joint>
    <joint name="sonar_joint" type="fixed">
        <origin rpy="0 1.5707963267948966 0" xyz="-0.16 0.0 -0.012" />
        <parent link="base_link" />
        <child link="sonar_link" />
    </joint>
    <link name="sonar_link">
        
<inertial>
            <mass value="0.001" />
            <origin rpy="0 0 0" xyz="0 0 0" />
            <inertia ixx="0.000000017" ixy="0" ixz="0" iyy="0.000000017" iyz="0" izz="0.000000017" />
        </inertial>

        <visual>
            <origin rpy="0 0 0" xyz="0 0 0" />
            <geometry>
                <!--<box size="0.01 0.01 0.01" /> -->
                <mesh filename="package://hector_sensors_description/meshes/sonar_sensor/max_sonar_ez4.dae" />
            </geometry>
        </visual>
        <collision>
            <origin rpy="0 0 0" xyz="0 0 0" />
            <geometry>
                <box size="0.01 0.01 0.01" />
            </geometry>
        </collision>
    </link>
    <gazebo reference="sonar_link">
        <sensor name="sonar" type="ray">
            <always_on>true</always_on>
            <update_rate>10</update_rate>
            <pose>0 0 0 0 0 0</pose>
            <visualize>false</visualize>
            <ray>
                <scan>
                    <horizontal>
                        <samples>3</samples>
                        <resolution>1</resolution>
                        <min_angle>-0.3490658503988659</min_angle>
                        <max_angle>0.3490658503988659</max_angle>
                    </horizontal>
                    <vertical>
                        <samples>3</samples>
                        <resolution>1</resolution>
                        <min_angle>-0.3490658503988659</min_angle>
                        <max_angle>0.3490658503988659</max_angle>
                    </vertical>
                </scan>
                <range>
                    <min>0.03</min>
                    <max>3.0</max>
                    <resolution>0.01</resolution>
                </range>
            </ray>
            <plugin filename="libhector_gazebo_ros_sonar.so" name="gazebo_ros_sonar_controller">
                <gaussianNoise>0.005</gaussianNoise>
                <topicName>sonar_height</topicName>
                <frameId>sonar_link</frameId>
            </plugin>
        </sensor>
    </gazebo>
    <link name="movable_link">
        <visual>
            <origin rpy="1.5707963267948966 0 0" xyz="0 0 0" />
            <geometry>
                <cylinder length="0.01" radius="0.03" />
            </geometry>
        </visual>
        <collision>
            <origin rpy="1.5707963267948966 0 0" xyz="0 0 0" />
            <geometry>
                <cylinder length="0.01" radius="0.03" />
            </geometry>
        </collision>
        
<inertial>
            <mass value="0.1" />
            <inertia ixx="0.03" ixy="0.0" ixz="0.0" iyy="0.03" iyz="0.0" izz="0.03" />
        </inertial>

    </link>
    <joint name="movable_camera_joint" type="revolute">
        <origin rpy="0.0 0.0 0.0" xyz="0 0 -0.055" />
        <parent link="fixedarm_link" />
        <child link="movable_link" />
        <axis xyz="0 -1 0" />
        <limit effort="2" lower="-1.5707963267948966" upper="0" velocity="2.0" />
    </joint>
    <joint name="camera_joint" type="fixed">
        <origin rpy="0 0 0" xyz="0.06 0.0 -0.03" />
        <parent link="movable_link" />
        <child link="camera_link" />
    </joint>
    <link name="camera_link">
        
<inertial>
            <mass value="0.01" />
            <origin xyz="0 0 0" />
            <inertia ixx="4.9000000000000005e-06" ixy="0.0" ixz="0.0" iyy="4.9000000000000005e-06" iyz="0.0" izz="4.9000000000000005e-06" />
        </inertial>

        <visual>
            <origin rpy="0 0 0" xyz="0 0 0" />
            <geometry>
                <mesh filename="package://hector_sensors_description/meshes/kinect_camera/kinect_camera_simple.dae" />
            </geometry>
        </visual>
        <collision>
            <origin rpy="0 0 0" xyz="0 0 0" />
            <geometry>
                <mesh filename="package://hector_sensors_description/meshes/kinect_camera/kinect_camera_simple.stl" />
            </geometry>
        </collision>
    </link>
    <joint name="camera_depth_joint" type="fixed">
        <origin rpy="0 0 0" xyz="0.0 -0.02 0.0" />
        <parent link="camera_link" />
        <child link="camera_depth_frame" />
    </joint>
    <link name="camera_depth_frame" />
    <joint name="camera_depth_optical_joint" type="fixed">
        <origin rpy="-1.5707963267948966 0.0 -1.5707963267948966" xyz="0 0 0" />
        <parent link="camera_depth_frame" />
        <child link="camera_depth_optical_frame" />
    </joint>
    <link name="camera_depth_optical_frame" />
    <joint name="camera_rgb_joint" type="fixed">
        <origin rpy="0 0 0" xyz="0.0 -0.0125 0.0" />
        <parent link="camera_link" />
        <child link="camera_rgb_frame" />
    </joint>
    <link name="camera_rgb_frame" />
    <joint name="camera_rgb_optical_joint" type="fixed">
        <origin rpy="-1.5707963267948966 0.0 -1.5707963267948966" xyz="0 0 0" />
        <parent link="camera_rgb_frame" />
        <child link="camera_rgb_optical_frame" />
    </joint>
    <link name="camera_rgb_optical_frame" />
    <gazebo reference="camera_depth_frame">
        <sensor name="camera" type="depth">
            <update_rate>10</update_rate>
            <camera>
                <horizontal_fov>1.5707963267948966</horizontal_fov>
                <image>
                    <format>B8G8R8</format>
                    <width>640</width>
                    <height>480</height>
                </image>
                <clip>
                    <near>0.1</near>
                    <far>100</far>
                </clip>
            </camera>
            <plugin filename="libgazebo_ros_openni_kinect.so" name="camera_camera_controller">
                <imageTopicName>camera/rgb/image_raw</imageTopicName>
                <cameraInfoTopicName>camera/rgb/camera_info</cameraInfoTopicName>
                <depthImageTopicName>camera/depth/image_raw</depthImageTopicName>
                <depthImageCameraInfoTopicName>camera/depth/camera_info</depthImageCameraInfoTopicName>
                <pointCloudTopicName>camera/depth/points</pointCloudTopicName>
                <frameName>camera_depth_optical_frame</frameName>
            </plugin>
        </sensor>
    </gazebo>
    
<transmission name="trans_movable_camera_joint">
        <type>transmission_interface/SimpleTransmission</type>
        <joint name="movable_camera_joint">
            <hardwareInterface>hardware_interface/PositionJointInterface</hardwareInterface>
        </joint>
        <actuator name="movable_camera_joint_motor">
            <hardwareInterface>hardware_interface/PositionJointInterface</hardwareInterface>
            <mechanicalReduction>1</mechanicalReduction>
        </actuator>
    </transmission>
    <!--<xacro:kinect_camera name="camera" parent="base_link">
        <origin xyz="0.23 0.0 -0.1" rpy="0 0 0"/>
    </xacro:kinect_camera>-->
    <!--<gazebo>
        <plugin name="gazebo_ros_control" filename="libgazebo_ros_control.so">
            <robotNamespace>/</robotNamespace>
        </plugin>
    </gazebo>-->
    <transmission name="trans_movable_camera_joint">
        <type>transmission_interface/SimpleTransmission</type>
        <joint name="movable_camera_joint">
            <hardwareInterface>hardware_interface/PositionJointInterface</hardwareInterface>
        </joint>
        <actuator name="movable_camera_joint_motor">
            <hardwareInterface>hardware_interface/PositionJointInterface</hardwareInterface>
            <mechanicalReduction>1</mechanicalReduction>
        </actuator>
    </transmission>
    <gazebo>
        <plugin name="gazebo_ros_control" filename="libgazebo_ros_control.so">
            <robotNamespace>/</robotNamespace>
        </plugin>
    </gazebo>
</robot>